Workbook

Sheet 5.ID
A1: Do Not Alter or Delete this Worksheet or you submission cannot be graded! | E1: DirVer
A2: Action | B2: Name | C2: Panther ID | D2: Date/Time | E2: S01
A3: Start S01 | B3: Ahadu Solomon | C3: 202020202 | D3: 44459.23 | E3: Microsoft Office User
A4: Starter Sheet | B4: None | C4: 0 | D4: 43831
E5: Welcome to Microsoft Excel version 16.53 build 912 running on Macintosh (Intel) Version 11.2.3 (Build 20D91)!

Sheet Pivot Table and Chart Pt1
A1: Month | B1: Demand
A2: 43831 | B2: 2323 | D2: Sum of Demand | E2: Column Labels | P2: 1. Copy your data set to columns A and B, leave the labels
A3: 43862 | B3: 2804 | D3: Row Labels | E3: 2020 | F3: 2021 | G3: 2022 | H3: Grand Total | P3: 2. Create a pivot table selecting Existing Worksheet at location D2
A4: 43891 | B4: 2469 | D4: Jan | E4: 2323 | F4: 2429 | G4: 2712 | H4: 7464 | P4: 3. Confirm that there is no data from earlier than Jan 2019, and then remove that line
A5: 43922 | B5: 3278 | D5: Feb | E5: 2804 | F5: 2495 | G5: 3229 | H5: 8528 | P5: 4. Create a Pivot Graph that looks like the one given in the Project instructions on Csepub
A6: 43952 | B6: 3617 | D6: Mar | E6: 2469 | F6: 2595 | G6: 3077 | H6: 8141 | P6: 5. Insert the trend line for 2022 and include the equation
A7: 43983 | B7: 2669 | D7: Apr | E7: 3278 | F7: 3383 | G7: 3646 | H7: 10307
A8: 44013 | B8: 2010 | D8: May | E8: 3617 | F8: 3426 | G8: 3998 | H8: 11041
A9: 44044 | B9: 2715 | D9: Jun | E9: 2669 | F9: 3654 | G9: 4062 | H9: 10385
A10: 44075 | B10: 2890 | D10: Jul | E10: 2010 | F10: 2629 | G10: 3171 | H10: 7810
A11: 44105 | B11: 2973 | D11: Aug | E11: 2715 | F11: 2996 | G11: 3638 | H11: 9349
A12: 44136 | B12: 3485 | D12: Sep | E12: 2890 | F12: 3150 | G12: 3623 | H12: 9663
A13: 44166 | B13: 4548 | D13: Oct | E13: 2973 | F13: 3924 | G13: 4050 | H13: 10947
A14: 44197 | B14: 2429 | D14: Nov | E14: 3485 | F14: 4185 | G14: 4528 | H14: 12198
A15: 44228 | B15: 2495 | D15: Dec | E15: 4548 | F15: 4982 | G15: 5702 | H15: 15232
A16: 44256 | B16: 2595 | D16: Grand Total | E16: 35781 | F16: 39848 | G16: 45436 | H16: 121065
A17: 44287 | B17: 3383
A18: 44317 | B18: 3426
A19: 44348 | B19: 3654
A20: 44378 | B20: 2629
A21: 44409 | B21: 2996
A22: 44440 | B22: 3150
A23: 44470 | B23: 3924
A24: 44501 | B24: 4185
A25: 44531 | B25: 4982
A26: 44562 | B26: 2712
A27: 44593 | B27: 3229
A28: 44621 | B28: 3077
... A37: 44896 | B37: 5702

Sheet SI and regression Pt 2
A1: Month | B1: Demand | C1: Monthly average by Year (demand w/out Seasonality | D1: Seasonal Index | E1: 3 year Average SI | F1: Deseasonalized | G1: Time period | J1: Regression Output
A2: 43831 | B2: =GETPIVOTDATA("Demand",'Pivot Table and Chart Pt1'!$D$2,"Months (Month)",1,"Years (Month)",2020) -> 2323 | D2: =B2/$C$13 -> 0.77907269 | E2: =AVERAGE(D2,D14,D26) -> 0.74227085 | F2: =B2/E2 -> 3129.5854 | G2: 1 | I2: CLICK CELL J2 as output cell for regression | J2: SUMMARY OUTPUT
A3: 43862 | B3: =GETPIVOTDATA("Demand",'Pivot Table and Chart Pt1'!$D$2,"Months (Month)",2,"Years (Month)",2020) -> 2804 | D3: =B3/$C$13 -> 0.94038736 | E3: =AVERAGE(D3,D15,D27) -> 0.84818215 | F3: =B3/E3 -> 3305.8937 | G3: 2
A4: 43891 | B4: =GETPIVOTDATA("Demand",'Pivot Table and Chart Pt1'!$D$2,"Months (Month)",3,"Years (Month)",2020) -> 2469 | D4: =B4/$C$13 -> 0.82803723 | E4: =AVERAGE(D4,D16,D28) -> 0.80738879 | F4: =B4/E4 -> 3058.0063 | G4: 3 | J4: Regression Statistics
A5: 43922 | B5: =GETPIVOTDATA("Demand",'Pivot Table and Chart Pt1'!$D$2,"Months (Month)",4,"Years (Month)",2020) -> 3278 | D5: =B5/$C$13 -> 1.0993544 | E5: =AVERAGE(D5,D17,D29) -> 1.0270209 | F5: =B5/E5 -> 3191.756 | G5: 4 | J5: Multiple R | K5: 0.82084274
A6: 43952 | B6: =GETPIVOTDATA("Demand",'Pivot Table and Chart Pt1'!$D$2,"Months (Month)",5,"Years (Month)",2020) -> 3617 | D6: =B6/$C$13 -> 1.213046 | E6: =AVERAGE(D6,D18,D30) -> 1.1002231 | F6: =B6/E6 -> 3287.515 | G6: 5 | J6: R Square | K6: 0.6737828
A7: 43983 | B7: =GETPIVOTDATA("Demand",'Pivot Table and Chart Pt1'!$D$2,"Months (Month)",6,"Years (Month)",2020) -> 2669 | D7: =B7/$C$13 -> 0.89511193 | E7: =AVERAGE(D7,D19,D31) -> 1.0227664 | F7: =B7/E7 -> 2609.5891 | G7: 6 | J7: Adjusted R Square | K7: 0.66418818
A8: 44013 | B8: =GETPIVOTDATA("Demand",'Pivot Table and Chart Pt1'!$D$2,"Months (Month)",7,"Years (Month)",2020) -> 2010 | D8: =B8/$C$13 -> 0.67410078 | E8: =AVERAGE(D8,D20,D32) -> 0.76776499 | F8: =B8/E8 -> 2617.9886 | G8: 7 | J8: Standard Error | K8: 225.11471
A9: 44044 | B9: =GETPIVOTDATA("Demand",'Pivot Table and Chart Pt1'!$D$2,"Months (Month)",8,"Years (Month)",2020) -> 2715 | D9: =B9/$C$13 -> 0.91053911 | E9: =AVERAGE(D9,D21,D33) -> 0.92453053 | F9: =B9/E9 -> 2936.6256 | G9: 8 | J9: Observations | K9: 36
A10: 44075 | B10: =GETPIVOTDATA("Demand",'Pivot Table and Chart Pt1'!$D$2,"Months (Month)",9,"Years (Month)",2020) -> 2890 | D10: =B10/$C$13 -> 0.96922948 | E10: =AVERAGE(D10,D22,D34) -> 0.95823219 | F10: =B10/E10 -> 3015.9705 | G10: 9
A11: 44105 | B11: =GETPIVOTDATA("Demand",'Pivot Table and Chart Pt1'!$D$2,"Months (Month)",10,"Years (Month)",2020) -> 2973 | D11: =B11/$C$13 -> 0.99706548 | E11: =AVERAGE(D11,D23,D35) -> 1.0827974 | F11: =B11/E11 -> 2745.6659 | G11: 10 | J11: ANOVA
A12: 44136 | B12: =GETPIVOTDATA("Demand",'Pivot Table and Chart Pt1'!$D$2,"Months (Month)",11,"Years (Month)",2020) -> 3485 | D12: =B12/$C$13 -> 1.1687767 | E12: =AVERAGE(D12,D24,D36) -> 1.2083152 | F12: =B12/E12 -> 2884.1811 | G12: 11 | K12: df | L12: SS | M12: MS | N12: F | O12: Significance F
A13: 44166 | B13: =GETPIVOTDATA("Demand",'Pivot Table and Chart Pt1'!$D$2,"Months (Month)",12,"Years (Month)",2020) -> 4548 | C13: =AVERAGE(B2:B13) -> 2981.75 | D13: =B13/$C$13 -> 1.5252788 | E13: =AVERAGE(D13,D25,D37) -> 1.5105074 | F13: =B13/E13 -> 3010.9087 | G13: 12 | J13: Regression | K13: 1 | L13: 3558768.6 | M13: 3558768.6 | N13: 70.225039 | O13: 8.7638991e-10
A14: 44197 | B14: =GETPIVOTDATA("Demand",'Pivot Table and Chart Pt1'!$D$2,"Months (Month)",1,"Years (Month)",2021) -> 2429 | D14: =B14/$C$25 -> 0.73147962 | F14: =B14/E2 -> 3272.3904 | G14: 13 | J14: Residual | K14: 34 | L14: 1723005.5 | M14: 50676.633
A15: 44228 | B15: =GETPIVOTDATA("Demand",'Pivot Table and Chart Pt1'!$D$2,"Months (Month)",2,"Years (Month)",2021) -> 2495 | D15: =B15/$C$25 -> 0.75135515 | F15: =B15/E3 -> 2941.5851 | G15: 14 | J15: Total | K15: 35 | L15: 5281774.1
A16: 44256 | B16: =GETPIVOTDATA("Demand",'Pivot Table and Chart Pt1'!$D$2,"Months (Month)",3,"Years (Month)",2021) -> 2595 | D16: =B16/$C$25 -> 0.78146958 | F16: =B16/E4 -> 3214.0649 | G16: 15
A17: 44287 | B17: =GETPIVOTDATA("Demand",'Pivot Table and Chart Pt1'!$D$2,"Months (Month)",4,"Years (Month)",2021) -> 3383 | D17: =B17/$C$25 -> 1.0187713 | F17: =B17/E5 -> 3293.9934 | G17: 16 | K17: Coefficients | L17: Standard Error | M17: t Stat | N17: P-value | O17: Lower 95% | P17: Upper 95% | Q17: Lower 95.0% | R17: Upper 95.0%
A18: 44317 | B18: =GETPIVOTDATA("Demand",'Pivot Table and Chart Pt1'!$D$2,"Months (Month)",5,"Years (Month)",2021) -> 3426 | D18: =B18/$C$25 -> 1.0317205 | F18: =B18/E6 -> 3113.9138 | G18: 17 | J18: Intercept | K18: 2803.2973 | L18: 76.629331 | M18: 36.582563 | N18: 6.8666329e-29 | O18: 2647.5678 | P18: 2959.0268 | Q18: 2647.5678 | R18: 2959.0268
A19: 44348 | B19: =GETPIVOTDATA("Demand",'Pivot Table and Chart Pt1'!$D$2,"Months (Month)",6,"Years (Month)",2021) -> 3654 | D19: =B19/$C$25 -> 1.1003814 | F19: =B19/E7 -> 3572.6635 | G19: 18 | J19: X Variable 1 | K19: 30.265954 | L19: 3.6116725 | M19: 8.3800381 | N19: 8.7638991e-10 | O19: 22.926152 | P19: 37.605755 | Q19: 22.926152 | R19: 37.605755
A20: 44378 | B20: =GETPIVOTDATA("Demand",'Pivot Table and Chart Pt1'!$D$2,"Months (Month)",7,"Years (Month)",2021) -> 2629 | D20: =B20/$C$25 -> 0.79170849 | F20: =B20/E8 -> 3424.2249 | G20: 19
A21: 44409 | B21: =GETPIVOTDATA("Demand",'Pivot Table and Chart Pt1'!$D$2,"Months (Month)",8,"Years (Month)",2021) -> 2996 | D21: =B21/$C$25 -> 0.90222847 | F21: =B21/E9 -> 3240.5636 | G21: 20
A22: 44440 | B22: =GETPIVOTDATA("Demand",'Pivot Table and Chart Pt1'!$D$2,"Months (Month)",9,"Years (Month)",2021) -> 3150 | D22: =B22/$C$25 -> 0.9486047 | F22: =B22/E10 -> 3287.3035 | G22: 21
A23: 44470 | B23: =GETPIVOTDATA("Demand",'Pivot Table and Chart Pt1'!$D$2,"Months (Month)",10,"Years (Month)",2021) -> 3924 | D23: =B23/$C$25 -> 1.1816904 | F23: =B23/E11 -> 3623.9465 | G23: 22
A24: 44501 | B24: =GETPIVOTDATA("Demand",'Pivot Table and Chart Pt1'!$D$2,"Months (Month)",11,"Years (Month)",2021) -> 4185 | D24: =B24/$C$25 -> 1.2602891 | F24: =B24/E12 -> 3463.5001 | G24: 23
A25: 44531 | B25: =GETPIVOTDATA("Demand",'Pivot Table and Chart Pt1'!$D$2,"Months (Month)",12,"Years (Month)",2021) -> 4982 | C25: =AVERAGE(B14:B25) -> 3320.6667 | D25: =B25/$C$25 -> 1.5003011 | F25: =B25/E13 -> 3298.2293 | G25: 24
A26: 44562 | B26: =GETPIVOTDATA("Demand",'Pivot Table and Chart Pt1'!$D$2,"Months (Month)",1,"Years (Month)",2022) -> 2712 | D26: =B26/$C$37 -> 0.71626023 | F26: =B26/E2 -> 3653.6528 | G26: 25
A27: 44593 | B27: =GETPIVOTDATA("Demand",'Pivot Table and Chart Pt1'!$D$2,"Months (Month)",2,"Years (Month)",2022) -> 3229 | D27: =B27/$C$37 -> 0.85280394 | F27: =B27/E3 -> 3806.9653 | G27: 26
A28: 44621 | B28: =GETPIVOTDATA("Demand",'Pivot Table and Chart Pt1'!$D$2,"Months (Month)",3,"Years (Month)",2022) -> 3077 | D28: =B28/$C$37 -> 0.81265957 | F28: =B28/E4 -> 3811.0512 | G28: 27
A29: 44652 | B29: =GETPIVOTDATA("Demand",'Pivot Table and Chart Pt1'!$D$2,"Months (Month)",4,"Years (Month)",2022) -> 3646 | D29: =B29/$C$37 -> 0.96293688 | F29: =B29/E5 -> 3550.0739 | G29: 28
A30: 44682 | B30: =GETPIVOTDATA("Demand",'Pivot Table and Chart Pt1'!$D$2,"Months (Month)",5,"Years (Month)",2022) -> 3998 | D30: =B30/$C$37 -> 1.0559028 | F30: =B30/E6 -> 3633.8084 | G30: 29
A31: 44713 | B31: =GETPIVOTDATA("Demand",'Pivot Table and Chart Pt1'!$D$2,"Months (Month)",6,"Years (Month)",2022) -> 4062 | D31: =B31/$C$37 -> 1.0728057 | F31: =B31/E7 -> 3971.5815 | G31: 30
A32: 44743 | B32: =GETPIVOTDATA("Demand",'Pivot Table and Chart Pt1'!$D$2,"Months (Month)",7,"Years (Month)",2022) -> 3171 | D32: =B32/$C$37 -> 0.83748569 | F32: =B32/E8 -> 4130.1701 | G32: 31
A33: 44774 | B33: =GETPIVOTDATA("Demand",'Pivot Table and Chart Pt1'!$D$2,"Months (Month)",8,"Years (Month)",2022) -> 3638 | D33: =B33/$C$37 -> 0.96082402 | F33: =B33/E9 -> 3934.9701 | G33: 32
A34: 44805 | B34: =GETPIVOTDATA("Demand",'Pivot Table and Chart Pt1'!$D$2,"Months (Month)",9,"Years (Month)",2022) -> 3623 | D34: =B34/$C$37 -> 0.9568624 | F34: =B34/E10 -> 3780.9208 | G34: 33
A35: 44835 | B35: =GETPIVOTDATA("Demand",'Pivot Table and Chart Pt1'!$D$2,"Months (Month)",10,"Years (Month)",2022) -> 4050 | D35: =B35/$C$37 -> 1.0696364 | F35: =B35/E11 -> 3740.3118 | G35: 34
A36: 44866 | B36: =GETPIVOTDATA("Demand",'Pivot Table and Chart Pt1'!$D$2,"Months (Month)",11,"Years (Month)",2022) -> 4528 | D36: =B36/$C$37 -> 1.1958799 | F36: =B36/E12 -> 3747.3664 | G36: 35 | H36: The below 2 columns are for the forecast for 2023
A37: 44896 | B37: =GETPIVOTDATA("Demand",'Pivot Table and Chart Pt1'!$D$2,"Months (Month)",12,"Years (Month)",2022) -> 5702 | C37: =AVERAGE(B26:B37) -> 3786.3333 | D37: =B37/$C$37 -> 1.5059424 | F37: =B37/E13 -> 3774.8904 | G37: 36 | H37: Deseasonalized forecast | I37: Seasonalized forecast, Use the average seasonal Index
B38: This space will be left blank. | G38: 37 | H38: =$K$19*G38+$K$18 -> 3923.1376 | I38: =H38*E2 -> 2912.0307
G39: 38 | H39: =$K$19*G39+$K$18 -> 3953.4035 | I39: =H39*E3 -> 3353.2063
B40: For the C and E columns above, only the blue boxes are needed | G40: 39 | H40: =$K$19*G40+$K$18 -> 3983.6695 | I40: =H40*E4 -> 3216.3701
...

Sheet Food Truck Demand
A1: Month | B1: Demand | C1: Hours operating/week | D1: Event location | E1: office location | H1: Demand is based off multiple regression
A2: 44470 | B2: 3634 | C2: 30 | D2: 1 | E2: 0 | H2: Use the data to the left from 10/2021 till 1/2023 to create a regression model
A3: 44501 | B3: 4550 | C3: 40 | D3: 0 | E3: 1 | H3: Use the model and the data in the blue box to create the demand for 2023
A4: 44531 | B4: 5330 | C4: 55 | D4: 1 | E4: 0
A5: 44562 | B5: 3100 | C5: 30 | D5: 0 | E5: 1 | H5: Event and office location are dummy variables.
A6: 44593 | B6: 2999 | C6: 30 | D6: 0 | E6: 1 | H6: Since these are the only 2 possible locations. This means that if they aren't at an Event location, they will be at an office location.
A7: 44621 | B7: 3051 | C7: 35 | D7: 1 | E7: 0 | H7: Therefore you only need to use 1 ( such as just the Event column) in the Regression, since by default a 0 in the event column means they are at an office location.
A8: 44652 | B8: 3753 | C8: 35 | D8: 0 | E8: 1
A9: 44682 | B9: 3709 | C9: 35 | D9: 0 | E9: 1
A10: 44713 | B10: 3930 | C10: 40 | D10: 1 | E10: 0
A11: 44743 | B11: 2949 | C11: 40 | D11: 0 | E11: 1
A12: 44774 | B12: 3348 | C12: 45 | D12: 0 | E12: 1
A13: 44805 | B13: 3400 | C13: 40 | D13: 0 | E13: 1
A14: 44835 | B14: 4400 | C14: 55 | D14: 1 | E14: 0
A15: 44866 | B15: 5079 | C15: 55 | D15: 1 | E15: 0
A16: 44896 | B16: 6087 | C16: 60 | D16: 1 | E16: 0
A17: 44927 | B17: =$L$39*C17+$L$40*D17+$L$38 -> 1949.7956 | C17: 15 | D17: 0 | E17: 1 | H17: This Blue box represent the variables to use in the regression equation to predict the demand for 2023.
A18: 44958 | B18: =$L$39*C18+$L$40*D18+$L$38 -> 2298.6423 | C18: 20 | D18: 0 | E18: 1
A19: 44986 | B19: =$L$39*C19+$L$40*D19+$L$38 -> 2298.6423 | C19: 20 | D19: 0 | E19: 1
A20: 45017 | B20: =$L$39*C20+$L$40*D20+$L$38 -> 2647.4891 | C20: 25 | D20: 0 | E20: 1
A21: 45047 | B21: =$L$39*C21+$L$40*D21+$L$38 -> 2647.4891 | C21: 25 | D21: 0 | E21: 1
A22: 45078 | B22: =$L$39*C22+$L$40*D22+$L$38 -> 3654.3723 | C22: 35 | D22: 1 | E22: 0 | K22: SUMMARY OUTPUT
A23: 45108 | B23: =$L$39*C23+$L$40*D23+$L$38 -> 3654.3723 | C23: 35 | D23: 1 | E23: 0
A24: 45139 | B24: =$L$39*C24+$L$40*D24+$L$38 -> 2647.4891 | C24: 25 | D24: 0 | E24: 1 | K24: Regression Statistics
A25: 45170 | B25: =$L$39*C25+$L$40*D25+$L$38 -> 2996.3358 | C25: 30 | D25: 0 | E25: 1 | K25: Multiple R | L25: 0.84434541
A26: 45200 | B26: =$L$39*C26+$L$40*D26+$L$38 -> 4003.219 | C26: 40 | D26: 1 | E26: 0 | K26: R Square | L26: 0.71291916
A27: 45231 | B27: =$L$39*C27+$L$40*D27+$L$38 -> 4003.219 | C27: 40 | D27: 1 | E27: 0 | K27: Adjusted R Square | L27: 0.66507236
A28: 45261 | B28: =$L$39*C28+$L$40*D28+$L$38 -> 4352.0657 | C28: 45 | D28: 1 | E28: 0 | K28: Standard Error | L28: 549.18651
K29: Observations | L29: 15
K31: ANOVA
L32: df | M32: SS | N32: MS | O32: F | P32: Significance F
K33: Regression | L33: 2 | M33: 8987875.7 | N33: 4493937.9 | O33: 14.900037 | P33: 0.0005597901
K34: Residual | L34: 12 | M34: 3619269.9 | N34: 301605.82
K35: Total | L35: 14 | M35: 12607146
L37: Coefficients | M37: Standard Error | N37: t Stat | O37: P-value | P37: Lower 95% | Q37: Upper 95% | R37: Lower 95.0% | S37: Upper 95.0%
K38: Intercept | L38: 903.25547 | M38: 657.37506 | N38: 1.3740337 | O38: 0.19455225 | P38: -529.04173 | Q38: 2335.5527 | R38: -529.04173 | S38: 2335.5527
K39: Hours operating/week | L39: 69.769343 | M39: 17.031744 | N39: 4.0964297 | O39: 0.0014817974 | P39: 32.66036 | Q39: 106.87833 | R39: 32.66036 | S39: 106.87833
K40: Event location | L40: 309.18978 | M40: 333.72162 | N40: 0.92649011 | O40: 0.37245001 | P40: -417.92717 | Q40: 1036.3067 | R40: -417.92717 | S40: 1036.3067

Sheet Financial information  FT
A1: Donut Information for Food Truck
A2: Based on the below data, create the profit model for Donuts to Go.
A3: Assume that each customer will buy one donut and one cup of coffee
I4: Row Labels | J4: Sum of Expense/revenue FT
C5: new | D5: Drop Production since flexible hours and limited storage space | I5: Fixed Expense | J5: 5045
A6: Item | B6: Profit Model label | C6: Expense/revenue FT | I6: Rev: Coffee | J6: 2.99
A7: Revenue: Cup of Coffee | B7: Rev: Coffee | C7: 2.99 | I7: Rev: Donut | J7: 2.5
A8: Revenue: Donut | B8: Rev: Donut | C8: 2.5 | I8: Variable Expense coffee | J8: 0.5
A9: Donut ingredients per donunt) | B9: Variable Expense donut | C9: 0.5 | I9: Variable Expense donut | J9: 0.6
A10: paper products: napkins, plates etc per Donut | B10: Variable Expense donut | C10: 0.1 | I10: Grand Total | J10: 5051.59
A11: Insurance | B11: Fixed Expense | C11: 150
A12: Maintenance & Repairs to equipment | B12: Fixed Expense | C12: 300
A13: Marketing & Promotion: Advertising | B13: Fixed Expense | C13: 0 | D13: No advertising, Friend doing locations on Insta and Facebook
A14: Coffee | B14: Variable Expense coffee | C14: 0.35
A15: Coffee cups | B15: Variable Expense coffee | C15: 0.15
A16: Payroll: Wages (Owner/ Manager) | B16: Fixed Expense | C16: 2400
A17: Payroll: Wages (per Employees) | B17: Fixed Expense | C17: 0 | D17: No other employees
A18: Donut and Coffee equipment rent | B18: Fixed Expense | C18: 0
A19: Professional Fees: Accounting | B19: Fixed Expense | C19: 50
A20: Professional Fees: Legal | B20: Fixed Expense | C20: 25
A21: Powdered and Liquid Beverages | B21: Fixed Expense | C21: 0
A22: Rent | B22: Fixed Expense | C22: 2120 | D22: No rent instead payment for lease on Food Truck.
A23: Supplies: Office | B23: Fixed Expense | C23: 0
A24: Utilities | B24: Fixed Expense | C24: 0
A30: Additional Data
A31: Food Truck
A32: Monthly Production | B32: make to order
A33: Lost Sales
A34: Day old revenue
A35: High demand, % above Average | B35: 0.05
A36: Low Demand, % below average | B36: 0.26
A62: Total

Sheet Franchise operations  Pt3
A1: FRANCHISE | B1: Reminder: Format Cells to show 2 decimal places | E1: Monthly Production | F1: Lost Sales | G1: Day old revenue
E2: ='Financial information 1 Pt1'!B31*(1+'Financial information 1 Pt1'!B38) -> 5280 | F2: ='Financial information 1 Pt1'!B32 -> 3 | G2: ='Financial information 1 Pt1'!B33 -> 1.25
A3: AVERAGE DEMAND
A4: Month | B4: 44927 | C4: 44958 | D4: 44986 | E4: 45017 | F4: 45047 | G4: 45078 | H4: 45108 | I4: 45139 | J4: 45170 | K4: 45200 | L4: 45231 | M4: 45261 | N4: Yearly Total
A5: Demand | B5: ='Current operations Pt3 '!B5*(1+'Financial information 1 Pt1'!$B$39) -> 3552.6774 | C5: ='Current operations Pt3 '!C5*(1+'Financial information 1 Pt1'!$B$39) -> 4090.9117 | D5: ='Current operations Pt3 '!D5*(1+'Financial information 1 Pt1'!$B$39) -> 3923.9715 | E5: ='Current operations Pt3 '!E5*(1+'Financial information 1 Pt1'!$B$39) -> 5029.3225 | F5: ='Current operations Pt3 '!F5*(1+'Financial information 1 Pt1'!$B$39) -> 5428.4191 | G5: ='Current operations Pt3 '!G5*(1+'Financial information 1 Pt1'!$B$39) -> 5084.0183 | H5: ='Current operations Pt3 '!H5*(1+'Financial information 1 Pt1'!$B$39) -> 3844.794 | I5: ='Current operations Pt3 '!I5*(1+'Financial information 1 Pt1'!$B$39) -> 4663.9783 | ... M5: ='Current operations Pt3 '!M5*(1+'Financial information 1 Pt1'!$B$39) -> 7843.1543 | N5: =SUM(B5:M5) -> 60102.409
A6: satisfied demand | B6: =MIN(B5,$E$2) -> 3552.6774 | C6: =MIN(C5,$E$2) -> 4090.9117 | D6: =MIN(D5,$E$2) -> 3923.9715 | E6: =MIN(E5,$E$2) -> 5029.3225 | F6: =MIN(F5,$E$2) -> 5280 | G6: =MIN(G5,$E$2) -> 5084.0183 | H6: =MIN(H5,$E$2) -> 3844.794 | I6: =MIN(I5,$E$2) -> 4663.9783 | ... M6: =MIN(M5,$E$2) -> 5280 | N6: =SUM(B6:M6) -> 56179.049
A7: Extra donuts(over) | B7: =IF(B5<$E$2,$E$2-B5,0) -> 1727.3226 | C7: =IF(C5<$E$2,$E$2-C5,0) -> 1189.0883 | D7: =IF(D5<$E$2,$E$2-D5,0) -> 1356.0285 | E7: =IF(E5<$E$2,$E$2-E5,0) -> 250.67753 | F7: =IF(F5<$E$2,$E$2-F5,0) -> 0 | G7: =IF(G5<$E$2,$E$2-G5,0) -> 195.98167 | H7: =IF(H5<$E$2,$E$2-H5,0) -> 1435.206 | I7: =IF(I5<$E$2,$E$2-I5,0) -> 616.02167 | ... M7: =IF(M5<$E$2,$E$2-M5,0) -> 0 | N7: =SUM(B7:M7) -> 7180.951
A8: Unsatisfied customers (short) | B8: =IF(B5>$E$2,B5-$E$2,0) -> 0 | C8: =IF(C5>$E$2,C5-$E$2,0) -> 0 | D8: =IF(D5>$E$2,D5-$E$2,0) -> 0 | E8: =IF(E5>$E$2,E5-$E$2,0) -> 0 | F8: =IF(F5>$E$2,F5-$E$2,0) -> 148.41915 | G8: =IF(G5>$E$2,G5-$E$2,0) -> 0 | H8: =IF(H5>$E$2,H5-$E$2,0) -> 0 | I8: =IF(I5>$E$2,I5-$E$2,0) -> 0 | ... M8: =IF(M5>$E$2,M5-$E$2,0) -> 2563.1543 | N8: =SUM(B8:M8) -> 3923.3601
A9: Revenue
A10: coffee | B10: =B6*'Financial information 1 Pt1'!$C$7 -> 10622.505 | C10: =C6*'Financial information 1 Pt1'!$C$7 -> 12231.826 | D10: =D6*'Financial information 1 Pt1'!$C$7 -> 11732.675 | E10: =E6*'Financial information 1 Pt1'!$C$7 -> 15037.674 | F10: =F6*'Financial information 1 Pt1'!$C$7 -> 15787.2 | G10: =G6*'Financial information 1 Pt1'!$C$7 -> 15201.215 | H10: =H6*'Financial information 1 Pt1'!$C$7 -> 11495.934 | I10: =I6*'Financial information 1 Pt1'!$C$7 -> 13945.295 | ... M10: =M6*'Financial information 1 Pt1'!$C$7 -> 15787.2 | N10: =SUM(B10:M10) -> 167975.36
A11: donut | B11: =B6*'Financial information 1 Pt1'!$C$8 -> 8881.6935 | C11: =C6*'Financial information 1 Pt1'!$C$8 -> 10227.279 | D11: =D6*'Financial information 1 Pt1'!$C$8 -> 9809.9288 | E11: =E6*'Financial information 1 Pt1'!$C$8 -> 12573.306 | F11: =F6*'Financial information 1 Pt1'!$C$8 -> 13200 | G11: =G6*'Financial information 1 Pt1'!$C$8 -> 12710.046 | H11: =H6*'Financial information 1 Pt1'!$C$8 -> 9611.9851 | I11: =I6*'Financial information 1 Pt1'!$C$8 -> 11659.946 | ... M11: =M6*'Financial information 1 Pt1'!$C$8 -> 13200 | N11: =SUM(B11:M11) -> 140447.62
A12: Revenue from day old sales | B12: =B7*$G$2 -> 2159.1532 | C12: =C7*$G$2 -> 1486.3604 | D12: =D7*$G$2 -> 1695.0356 | E12: =E7*$G$2 -> 313.34691 | F12: =F7*$G$2 -> 0 | G12: =G7*$G$2 -> 244.97709 | H12: =H7*$G$2 -> 1794.0075 | I12: =I7*$G$2 -> 770.02709 | ... M12: =M7*$G$2 -> 0 | N12: =SUM(B12:M12) -> 8976.1887
A13: Total Revenue | B13: =SUM(B10:B12) -> 21663.352 | C13: =SUM(C10:C12) -> 23945.466 | D13: =SUM(D10:D12) -> 23237.639 | E13: =SUM(E10:E12) -> 27924.327 | F13: =SUM(F10:F12) -> 28987.2 | G13: =SUM(G10:G12) -> 28156.238 | H13: =SUM(H10:H12) -> 22901.927 | I13: =SUM(I10:I12) -> 26375.268 | ... M13: =SUM(M10:M12) -> 28987.2 | N13: =SUM(B13:M13) -> 317399.17
A14: Expenses
A15: Fixed Expenses | B15: =GETPIVOTDATA("Expense/revenue",'Financial information 1 Pt1'!$E$5,"Profit Model label","Fixed Expense")+'Financial information 1 Pt1'!$B$37 -> 10150 | C15: =GETPIVOTDATA("Expense/revenue",'Financial information 1 Pt1'!$E$5,"Profit Model label","Fixed Expense")+'Financial information 1 Pt1'!$B$37 -> 10150 | D15: =GETPIVOTDATA("Expense/revenue",'Financial information 1 Pt1'!$E$5,"Profit Model label","Fixed Expense")+'Financial information 1 Pt1'!$B$37 -> 10150 | E15: =GETPIVOTDATA("Expense/revenue",'Financial information 1 Pt1'!$E$5,"Profit Model label","Fixed Expense")+'Financial information 1 Pt1'!$B$37 -> 10150 | F15: =GETPIVOTDATA("Expense/revenue",'Financial information 1 Pt1'!$E$5,"Profit Model label","Fixed Expense")+'Financial information 1 Pt1'!$B$37 -> 10150 | G15: =GETPIVOTDATA("Expense/revenue",'Financial information 1 Pt1'!$E$5,"Profit Model label","Fixed Expense")+'Financial information 1 Pt1'!$B$37 -> 10150 | H15: =GETPIVOTDATA("Expense/revenue",'Financial information 1 Pt1'!$E$5,"Profit Model label","Fixed Expense")+'Financial information 1 Pt1'!$B$37 -> 10150 | I15: =GETPIVOTDATA("Expense/revenue",'Financial information 1 Pt1'!$E$5,"Profit Model label","Fixed Expense")+'Financial information 1 Pt1'!$B$37 -> 10150 | ... M15: =GETPIVOTDATA("Expense/revenue",'Financial information 1 Pt1'!$E$5,"Profit Model label","Fixed Expense")+'Financial information 1 Pt1'!$B$37 -> 10150 | N15: =SUM(B15:M15) -> 121800
A16: Total Fixed Expense | B16: =GETPIVOTDATA("Expense/revenue",'Financial information 1 Pt1'!$E$5,"Profit Model label","Fixed Expense")+'Financial information 1 Pt1'!$B$37 -> 10150 | C16: =GETPIVOTDATA("Expense/revenue",'Financial information 1 Pt1'!$E$5,"Profit Model label","Fixed Expense")+'Financial information 1 Pt1'!$B$37 -> 10150 | D16: =GETPIVOTDATA("Expense/revenue",'Financial information 1 Pt1'!$E$5,"Profit Model label","Fixed Expense")+'Financial information 1 Pt1'!$B$37 -> 10150 | E16: =GETPIVOTDATA("Expense/revenue",'Financial information 1 Pt1'!$E$5,"Profit Model label","Fixed Expense")+'Financial information 1 Pt1'!$B$37 -> 10150 | F16: =GETPIVOTDATA("Expense/revenue",'Financial information 1 Pt1'!$E$5,"Profit Model label","Fixed Expense")+'Financial information 1 Pt1'!$B$37 -> 10150 | G16: =GETPIVOTDATA("Expense/revenue",'Financial information 1 Pt1'!$E$5,"Profit Model label","Fixed Expense")+'Financial information 1 Pt1'!$B$37 -> 10150 | H16: =GETPIVOTDATA("Expense/revenue",'Financial information 1 Pt1'!$E$5,"Profit Model label","Fixed Expense")+'Financial information 1 Pt1'!$B$37 -> 10150 | I16: =GETPIVOTDATA("Expense/revenue",'Financial information 1 Pt1'!$E$5,"Profit Model label","Fixed Expense")+'Financial information 1 Pt1'!$B$37 -> 10150 | ... M16: =GETPIVOTDATA("Expense/revenue",'Financial information 1 Pt1'!$E$5,"Profit Model label","Fixed Expense")+'Financial information 1 Pt1'!$B$37 -> 10150 | N16: =SUM(B16:M16) -> 121800
A18: Variable Expenses
A19: Coffee Variable expense | B19: =$E$2*GETPIVOTDATA("Expense/revenue",'Financial information 1 Pt1'!$E$5,"Profit Model label","Variable Expense: Coffee") -> 2640 | C19: =$E$2*GETPIVOTDATA("Expense/revenue",'Financial information 1 Pt1'!$E$5,"Profit Model label","Variable Expense: Coffee") -> 2640 | D19: =$E$2*GETPIVOTDATA("Expense/revenue",'Financial information 1 Pt1'!$E$5,"Profit Model label","Variable Expense: Coffee") -> 2640 | E19: =$E$2*GETPIVOTDATA("Expense/revenue",'Financial information 1 Pt1'!$E$5,"Profit Model label","Variable Expense: Coffee") -> 2640 | F19: =$E$2*GETPIVOTDATA("Expense/revenue",'Financial information 1 Pt1'!$E$5,"Profit Model label","Variable Expense: Coffee") -> 2640 | G19: =$E$2*GETPIVOTDATA("Expense/revenue",'Financial information 1 Pt1'!$E$5,"Profit Model label","Variable Expense: Coffee") -> 2640 | H19: =$E$2*GETPIVOTDATA("Expense/revenue",'Financial information 1 Pt1'!$E$5,"Profit Model label","Variable Expense: Coffee") -> 2640 | I19: =$E$2*GETPIVOTDATA("Expense/revenue",'Financial information 1 Pt1'!$E$5,"Profit Model label","Variable Expense: Coffee") -> 2640 | ... M19: =$E$2*GETPIVOTDATA("Expense/revenue",'Financial information 1 Pt1'!$E$5,"Profit Model label","Variable Expense: Coffee") -> 2640 | N19: =SUM(B19:M19) -> 31680
A20: Donut Variable expense | B20: =$E$2*GETPIVOTDATA("Expense/revenue",'Financial information 1 Pt1'!$E$5,"Profit Model label","Variable Expense: Donut") -> 3168 | C20: =$E$2*GETPIVOTDATA("Expense/revenue",'Financial information 1 Pt1'!$E$5,"Profit Model label","Variable Expense: Donut") -> 3168 | D20: =$E$2*GETPIVOTDATA("Expense/revenue",'Financial information 1 Pt1'!$E$5,"Profit Model label","Variable Expense: Donut") -> 3168 | E20: =$E$2*GETPIVOTDATA("Expense/revenue",'Financial information 1 Pt1'!$E$5,"Profit Model label","Variable Expense: Donut") -> 3168 | F20: =$E$2*GETPIVOTDATA("Expense/revenue",'Financial information 1 Pt1'!$E$5,"Profit Model label","Variable Expense: Donut") -> 3168 | G20: =$E$2*GETPIVOTDATA("Expense/revenue",'Financial information 1 Pt1'!$E$5,"Profit Model label","Variable Expense: Donut") -> 3168 | H20: =$E$2*GETPIVOTDATA("Expense/revenue",'Financial information 1 Pt1'!$E$5,"Profit Model label","Variable Expense: Donut") -> 3168 | I20: =$E$2*GETPIVOTDATA("Expense/revenue",'Financial information 1 Pt1'!$E$5,"Profit Model label","Variable Expense: Donut") -> 3168 | ... M20: =$E$2*GETPIVOTDATA("Expense/revenue",'Financial information 1 Pt1'!$E$5,"Profit Model label","Variable Expense: Donut") -> 3168 | N20: =SUM(B20:M20) -> 38016
A21: Total Variable Expenses | B21: =SUM(B19:B20) -> 5808 | C21: =SUM(C19:C20) -> 5808 | D21: =SUM(D19:D20) -> 5808 | E21: =SUM(E19:E20) -> 5808 | F21: =SUM(F19:F20) -> 5808 | G21: =SUM(G19:G20) -> 5808 | H21: =SUM(H19:H20) -> 5808 | I21: =SUM(I19:I20) -> 5808 | ... M21: =SUM(M19:M20) -> 5808 | N21: =SUM(B21:M21) -> 69696
A22: Expenses: due to lost sales | B22: =B8*$F$2 -> 0 | C22: =C8*$F$2 -> 0 | D22: =D8*$F$2 -> 0 | E22: =E8*$F$2 -> 0 | F22: =F8*$F$2 -> 445.25744 | G22: =G8*$F$2 -> 0 | H22: =H8*$F$2 -> 0 | I22: =I8*$F$2 -> 0 | ... M22: =M8*$F$2 -> 7689.4628 | N22: =SUM(B22:M22) -> 11770.08
A23: Total Expenses | B23: =B16+B21+B22 -> 15958 | C23: =C16+C21+C22 -> 15958 | D23: =D16+D21+D22 -> 15958 | E23: =E16+E21+E22 -> 15958 | F23: =F16+F21+F22 -> 16403.257 | G23: =G16+G21+G22 -> 15958 | H23: =H16+H21+H22 -> 15958 | I23: =I16+I21+I22 -> 15958 | ... M23: =M16+M21+M22 -> 23647.463 | N23: =SUM(B23:M23) -> 203266.08
A25: Profit Donuts and Coffee | B25: =B13-B23 -> 5705.3522 | C25: =C13-C23 -> 7987.4656 | D25: =D13-D23 -> 7279.6392 | E25: =E13-E23 -> 11966.327 | F25: =F13-F23 -> 12583.943 | G25: =G13-G23 -> 12198.238 | H25: =H13-H23 -> 6943.9267 | I25: =I13-I23 -> 10417.268 | ... M25: =M13-M23 -> 5339.7372 | N25: =SUM(B25:M25) -> 114133.09
B27: You should be able to copy from average to high and low and then just make some modifications
A28: HIGH DEMAND
A29: Month | B29: =B4 -> 44927 | C29: =C4 -> 44958 | D29: =D4 -> 44986 | E29: =E4 -> 45017 | F29: =F4 -> 45047 | G29: =G4 -> 45078 | H29: =H4 -> 45108 | I29: =I4 -> 45139 | ... M29: =M4 -> 45261 | N29: Yearly Total
A30: Demand | B30: =B5*(1+'Financial information 1 Pt1'!$B$34) -> 4334.2664 | C30: =C5*(1+'Financial information 1 Pt1'!$B$34) -> 4990.9123 | D30: =D5*(1+'Financial information 1 Pt1'!$B$34) -> 4787.2452 | E30: =E5*(1+'Financial information 1 Pt1'!$B$34) -> 6135.7734 | F30: =F5*(1+'Financial information 1 Pt1'!$B$34) -> 6622.6714 | G30: =G5*(1+'Financial information 1 Pt1'!$B$34) -> 6202.5024 | H30: =H5*(1+'Financial information 1 Pt1'!$B$34) -> 4690.6487 | I30: =I5*(1+'Financial information 1 Pt1'!$B$34) -> 5690.0536 | ... M30: =M5*(1+'Financial information 1 Pt1'!$B$34) -> 9568.6482 | N30: =SUM(B30:M30) -> 73324.939
A31: satisfied demand | B31: =MIN(B30,$E$2) -> 4334.2664 | C31: =MIN(C30,$E$2) -> 4990.9123 | D31: =MIN(D30,$E$2) -> 4787.2452 | E31: =MIN(E30,$E$2) -> 5280 | F31: =MIN(F30,$E$2) -> 5280 | G31: =MIN(G30,$E$2) -> 5280 | H31: =MIN(H30,$E$2) -> 4690.6487 | I31: =MIN(I30,$E$2) -> 5280 | ... M31: =MIN(M30,$E$2) -> 5280 | N31: =SUM(B31:M31) -> 61043.073
A32: Extra donuts(over) | B32: =IF(B30<$E$2,$E$2-B30,0) -> 945.73357 | C32: =IF(C30<$E$2,$E$2-C30,0) -> 289.08774 | D32: =IF(D30<$E$2,$E$2-D30,0) -> 492.75476 | E32: =IF(E30<$E$2,$E$2-E30,0) -> 0 | F32: =IF(F30<$E$2,$E$2-F30,0) -> 0 | G32: =IF(G30<$E$2,$E$2-G30,0) -> 0 | H32: =IF(H30<$E$2,$E$2-H30,0) -> 589.35129 | I32: =IF(I30<$E$2,$E$2-I30,0) -> 0 | ... M32: =IF(M30<$E$2,$E$2-M30,0) -> 0 | N32: =SUM(B32:M32) -> 2316.9274
A33: Unsatisfied customers (short) | B33: =IF(B30>$E$2,B30-$E$2,0) -> 0 | C33: =IF(C30>$E$2,C30-$E$2,0) -> 0 | D33: =IF(D30>$E$2,D30-$E$2,0) -> 0 | E33: =IF(E30>$E$2,E30-$E$2,0) -> 855.77341 | F33: =IF(F30>$E$2,F30-$E$2,0) -> 1342.6714 | G33: =IF(G30>$E$2,G30-$E$2,0) -> 922.50236 | H33: =IF(H30>$E$2,H30-$E$2,0) -> 0 | I33: =IF(I30>$E$2,I30-$E$2,0) -> 410.05356 | ... M33: =IF(M30>$E$2,M30-$E$2,0) -> 4288.6482 | N33: =SUM(B33:M33) -> 12281.866
A34: Revenue
A35: coffee | B35: =B31*'Financial information 1 Pt1'!$C$7 -> 12959.457 | C35: =C31*'Financial information 1 Pt1'!$C$7 -> 14922.828 | D35: =D31*'Financial information 1 Pt1'!$C$7 -> 14313.863 | E35: =E31*'Financial information 1 Pt1'!$C$7 -> 15787.2 | F35: =F31*'Financial information 1 Pt1'!$C$7 -> 15787.2 | G35: =G31*'Financial information 1 Pt1'!$C$7 -> 15787.2 | H35: =H31*'Financial information 1 Pt1'!$C$7 -> 14025.04 | I35: =I31*'Financial information 1 Pt1'!$C$7 -> 15787.2 | ... M35: =M31*'Financial information 1 Pt1'!$C$7 -> 15787.2 | N35: =SUM(B35:M35) -> 182518.79
A36: donut | B36: =B31*'Financial information 1 Pt1'!$C$8 -> 10835.666 | C36: =C31*'Financial information 1 Pt1'!$C$8 -> 12477.281 | D36: =D31*'Financial information 1 Pt1'!$C$8 -> 11968.113 | E36: =E31*'Financial information 1 Pt1'!$C$8 -> 13200 | F36: =F31*'Financial information 1 Pt1'!$C$8 -> 13200 | G36: =G31*'Financial information 1 Pt1'!$C$8 -> 13200 | H36: =H31*'Financial information 1 Pt1'!$C$8 -> 11726.622 | I36: =I31*'Financial information 1 Pt1'!$C$8 -> 13200 | ... M36: =M31*'Financial information 1 Pt1'!$C$8 -> 13200 | N36: =SUM(B36:M36) -> 152607.68
A37: Revenue from day old sales | B37: =B32*$G$2 -> 1182.167 | C37: =C32*$G$2 -> 361.35967 | D37: =D32*$G$2 -> 615.94345 | E37: =E32*$G$2 -> 0 | F37: =F32*$G$2 -> 0 | G37: =G32*$G$2 -> 0 | H37: =H32*$G$2 -> 736.68911 | I37: =I32*$G$2 -> 0 | ... M37: =M32*$G$2 -> 0 | N37: =SUM(B37:M37) -> 2896.1592
A38: Total Revenue | B38: =SUM(B35:B37) -> 24977.29 | C38: =SUM(C35:C37) -> 27761.468 | D38: =SUM(D35:D37) -> 26897.92 | E38: =SUM(E35:E37) -> 28987.2 | F38: =SUM(F35:F37) -> 28987.2 | G38: =SUM(G35:G37) -> 28987.2 | H38: =SUM(H35:H37) -> 26488.351 | I38: =SUM(I35:I37) -> 28987.2 | ... M38: =SUM(M35:M37) -> 28987.2 | N38: =SUM(B38:M38) -> 338022.63
A39: Expenses
A40: Fixed Expenses | B40: =GETPIVOTDATA("Expense/revenue",'Financial information 1 Pt1'!$E$5,"Profit Model label","Fixed Expense")+'Financial information 1 Pt1'!$B$37 -> 10150 | C40: =GETPIVOTDATA("Expense/revenue",'Financial information 1 Pt1'!$E$5,"Profit Model label","Fixed Expense")+'Financial information 1 Pt1'!$B$37 -> 10150 | D40: =GETPIVOTDATA("Expense/revenue",'Financial information 1 Pt1'!$E$5,"Profit Model label","Fixed Expense")+'Financial information 1 Pt1'!$B$37 -> 10150 | E40: =GETPIVOTDATA("Expense/revenue",'Financial information 1 Pt1'!$E$5,"Profit Model label","Fixed Expense")+'Financial information 1 Pt1'!$B$37 -> 10150 | F40: =GETPIVOTDATA("Expense/revenue",'Financial information 1 Pt1'!$E$5,"Profit Model label","Fixed Expense")+'Financial information 1 Pt1'!$B$37 -> 10150 | G40: =GETPIVOTDATA("Expense/revenue",'Financial information 1 Pt1'!$E$5,"Profit Model label","Fixed Expense")+'Financial information 1 Pt1'!$B$37 -> 10150 | H40: =GETPIVOTDATA("Expense/revenue",'Financial information 1 Pt1'!$E$5,"Profit Model label","Fixed Expense")+'Financial information 1 Pt1'!$B$37 -> 10150 | I40: =GETPIVOTDATA("Expense/revenue",'Financial information 1 Pt1'!$E$5,"Profit Model label","Fixed Expense")+'Financial information 1 Pt1'!$B$37 -> 10150 | ... M40: =GETPIVOTDATA("Expense/revenue",'Financial information 1 Pt1'!$E$5,"Profit Model label","Fixed Expense")+'Financial information 1 Pt1'!$B$37 -> 10150 | N40: =SUM(B40:M40) -> 121800
A41: Total Fixed Expense | B41: =GETPIVOTDATA("Expense/revenue",'Financial information 1 Pt1'!$E$5,"Profit Model label","Fixed Expense")+'Financial information 1 Pt1'!$B$37 -> 10150 | C41: =GETPIVOTDATA("Expense/revenue",'Financial information 1 Pt1'!$E$5,"Profit Model label","Fixed Expense")+'Financial information 1 Pt1'!$B$37 -> 10150 | D41: =GETPIVOTDATA("Expense/revenue",'Financial information 1 Pt1'!$E$5,"Profit Model label","Fixed Expense")+'Financial information 1 Pt1'!$B$37 -> 10150 | E41: =GETPIVOTDATA("Expense/revenue",'Financial information 1 Pt1'!$E$5,"Profit Model label","Fixed Expense")+'Financial information 1 Pt1'!$B$37 -> 10150 | F41: =GETPIVOTDATA("Expense/revenue",'Financial information 1 Pt1'!$E$5,"Profit Model label","Fixed Expense")+'Financial information 1 Pt1'!$B$37 -> 10150 | G41: =GETPIVOTDATA("Expense/revenue",'Financial information 1 Pt1'!$E$5,"Profit Model label","Fixed Expense")+'Financial information 1 Pt1'!$B$37 -> 10150 | H41: =GETPIVOTDATA("Expense/revenue",'Financial information 1 Pt1'!$E$5,"Profit Model label","Fixed Expense")+'Financial information 1 Pt1'!$B$37 -> 10150 | I41: =GETPIVOTDATA("Expense/revenue",'Financial information 1 Pt1'!$E$5,"Profit Model label","Fixed Expense")+'Financial information 1 Pt1'!$B$37 -> 10150 | ... M41: =GETPIVOTDATA("Expense/revenue",'Financial information 1 Pt1'!$E$5,"Profit Model label","Fixed Expense")+'Financial information 1 Pt1'!$B$37 -> 10150 | N41: =SUM(B41:M41) -> 121800
A43: Variable Expenses
A44: Coffee Variable expense | B44: =$E$2*GETPIVOTDATA("Expense/revenue",'Financial information 1 Pt1'!$E$5,"Profit Model label","Variable Expense: Coffee") -> 2640 | C44: =$E$2*GETPIVOTDATA("Expense/revenue",'Financial information 1 Pt1'!$E$5,"Profit Model label","Variable Expense: Coffee") -> 2640 | D44: =$E$2*GETPIVOTDATA("Expense/revenue",'Financial information 1 Pt1'!$E$5,"Profit Model label","Variable Expense: Coffee") -> 2640 | E44: =$E$2*GETPIVOTDATA("Expense/revenue",'Financial information 1 Pt1'!$E$5,"Profit Model label","Variable Expense: Coffee") -> 2640 | F44: =$E$2*GETPIVOTDATA("Expense/revenue",'Financial information 1 Pt1'!$E$5,"Profit Model label","Variable Expense: Coffee") -> 2640 | G44: =$E$2*GETPIVOTDATA("Expense/revenue",'Financial information 1 Pt1'!$E$5,"Profit Model label","Variable Expense: Coffee") -> 2640 | H44: =$E$2*GETPIVOTDATA("Expense/revenue",'Financial information 1 Pt1'!$E$5,"Profit Model label","Variable Expense: Coffee") -> 2640 | I44: =$E$2*GETPIVOTDATA("Expense/revenue",'Financial information 1 Pt1'!$E$5,"Profit Model label","Variable Expense: Coffee") -> 2640 | ... M44: =$E$2*GETPIVOTDATA("Expense/revenue",'Financial information 1 Pt1'!$E$5,"Profit Model label","Variable Expense: Coffee") -> 2640 | N44: =SUM(B44:M44) -> 31680
...

Sheet Current operations  Pt3 
A1: CURRENT OPERATIONS | B1: Reminder: Format Cells to show 2 decimal places | E1: Monthly Production | F1: Lost Sales | G1: Day old revenue | Z1: Fall 25
E2: ='Financial information 1 Pt1'!B31 -> 4000 | F2: ='Financial information 1 Pt1'!B32 -> 3 | G2: ='Financial information 1 Pt1'!B33 -> 1.25
A3: AVERAGE DEMAND
A4: Month | B4: 44927 | C4: 44958 | D4: 44986 | E4: 45017 | F4: 45047 | G4: 45078 | H4: 45108 | I4: 45139 | J4: 45170 | K4: 45200 | L4: 45231 | M4: 45261 | N4: Yearly Total
A5: Demand | B5: ='SI and regression Pt 2'!I38 -> 2912.0307 | C5: ='SI and regression Pt 2'!I39 -> 3353.2063 | D5: ='SI and regression Pt 2'!I40 -> 3216.3701 | E5: ='SI and regression Pt 2'!I41 -> 4122.3955 | F5: ='SI and regression Pt 2'!I42 -> 4449.5239 | G5: ='SI and regression Pt 2'!I43 -> 4167.2281 | H5: ='SI and regression Pt 2'!I44 -> 3151.4705 | I5: ='SI and regression Pt 2'!I45 -> 3822.9331 | J5: ='SI and regression Pt 2'!I46 -> 3991.2912 | K5: ='SI and regression Pt 2'!I47 -> 4542.9104 | L5: ='SI and regression Pt 2'!I48 -> 5106.0951 | M5: ='SI and regression Pt 2'!I49 -> 6428.815 | N5: =SUM(B5:M5) -> 49264.27
A6: satisfied demand | B6: =MIN(B5,$E$2) -> 2912.0307 | C6: =MIN(C5,$E$2) -> 3353.2063 | D6: =MIN(D5,$E$2) -> 3216.3701 | E6: =MIN(E5,$E$2) -> 4000 | F6: =MIN(F5,$E$2) -> 4000 | G6: =MIN(G5,$E$2) -> 4000 | H6: =MIN(H5,$E$2) -> 3151.4705 | I6: =MIN(I5,$E$2) -> 3822.9331 | ... M6: =MIN(M5,$E$2) -> 4000 | N6: =SUM(B6:M6) -> 44447.302
A7: Extra donuts(over) | B7: =IF(B5<$E$2,$E$2-B5,0) -> 1087.9693 | C7: =IF(C5<$E$2,$E$2-C5,0) -> 646.7937 | D7: =IF(D5<$E$2,$E$2-D5,0) -> 783.62991 | E7: =IF(E5<$E$2,$E$2-E5,0) -> 0 | F7: =IF(F5<$E$2,$E$2-F5,0) -> 0 | G7: =IF(G5<$E$2,$E$2-G5,0) -> 0 | H7: =IF(H5<$E$2,$E$2-H5,0) -> 848.52949 | I7: =IF(I5<$E$2,$E$2-I5,0) -> 177.06694 | ... M7: =IF(M5<$E$2,$E$2-M5,0) -> 0 | N7: =SUM(B7:M7) -> 3552.6982
A8: Unsatisfied customers (short) | B8: =IF(B5>$E$2,B5-$E$2,0) -> 0 | C8: =IF(C5>$E$2,C5-$E$2,0) -> 0 | D8: =IF(D5>$E$2,D5-$E$2,0) -> 0 | E8: =IF(E5>$E$2,E5-$E$2,0) -> 122.39547 | F8: =IF(F5>$E$2,F5-$E$2,0) -> 449.52389 | G8: =IF(G5>$E$2,G5-$E$2,0) -> 167.22814 | H8: =IF(H5>$E$2,H5-$E$2,0) -> 0 | I8: =IF(I5>$E$2,I5-$E$2,0) -> 0 | ... M8: =IF(M5>$E$2,M5-$E$2,0) -> 2428.815 | N8: =SUM(B8:M8) -> 4816.9679
A9: Revenue
A10: coffee | B10: =B6*'Financial information 1 Pt1'!$C$7 -> 8706.9717 | C10: =C6*'Financial information 1 Pt1'!$C$7 -> 10026.087 | D10: =D6*'Financial information 1 Pt1'!$C$7 -> 9616.9466 | E10: =E6*'Financial information 1 Pt1'!$C$7 -> 11960 | F10: =F6*'Financial information 1 Pt1'!$C$7 -> 11960 | G10: =G6*'Financial information 1 Pt1'!$C$7 -> 11960 | H10: =H6*'Financial information 1 Pt1'!$C$7 -> 9422.8968 | I10: =I6*'Financial information 1 Pt1'!$C$7 -> 11430.57 | ... M10: =M6*'Financial information 1 Pt1'!$C$7 -> 11960 | N10: =SUM(B10:M10) -> 132897.43
A11: donut | B11: =B6*'Financial information 1 Pt1'!$C$8 -> 7280.0766 | C11: =C6*'Financial information 1 Pt1'!$C$8 -> 8383.0158 | D11: =D6*'Financial information 1 Pt1'!$C$8 -> 8040.9252 | E11: =E6*'Financial information 1 Pt1'!$C$8 -> 10000 | F11: =F6*'Financial information 1 Pt1'!$C$8 -> 10000 | G11: =G6*'Financial information 1 Pt1'!$C$8 -> 10000 | H11: =H6*'Financial information 1 Pt1'!$C$8 -> 7878.6763 | I11: =I6*'Financial information 1 Pt1'!$C$8 -> 9557.3326 | ... M11: =M6*'Financial information 1 Pt1'!$C$8 -> 10000 | N11: =SUM(B11:M11) -> 111118.25
A12: Revenue from day old sales | B12: =B7*$G$2 -> 1359.9617 | C12: =C7*$G$2 -> 808.49212 | D12: =D7*$G$2 -> 979.53739 | E12: =E7*$G$2 -> 0 | F12: =F7*$G$2 -> 0 | G12: =G7*$G$2 -> 0 | H12: =H7*$G$2 -> 1060.6619 | I12: =I7*$G$2 -> 221.33368 | ... M12: =M7*$G$2 -> 0 | N12: =SUM(B12:M12) -> 4440.8727
A13: Total Revenue | B13: =SUM(B10:B12) -> 17347.01 | C13: =SUM(C10:C12) -> 19217.595 | D13: =SUM(D10:D12) -> 18637.409 | E13: =SUM(E10:E12) -> 21960 | F13: =SUM(F10:F12) -> 21960 | G13: =SUM(G10:G12) -> 21960 | H13: =SUM(H10:H12) -> 18362.235 | I13: =SUM(I10:I12) -> 21209.236 | ... N13: =SUM(N10:N12) -> 248456.56
A14: Expenses
A15: Fixed Expenses | B15: =GETPIVOTDATA("Expense/revenue",'Financial information 1 Pt1'!$E$5,"Profit Model label","Fixed Expense") -> 5800 | C15: =GETPIVOTDATA("Expense/revenue",'Financial information 1 Pt1'!$E$5,"Profit Model label","Fixed Expense") -> 5800 | D15: =GETPIVOTDATA("Expense/revenue",'Financial information 1 Pt1'!$E$5,"Profit Model label","Fixed Expense") -> 5800 | E15: =GETPIVOTDATA("Expense/revenue",'Financial information 1 Pt1'!$E$5,"Profit Model label","Fixed Expense") -> 5800 | F15: =GETPIVOTDATA("Expense/revenue",'Financial information 1 Pt1'!$E$5,"Profit Model label","Fixed Expense") -> 5800 | G15: =GETPIVOTDATA("Expense/revenue",'Financial information 1 Pt1'!$E$5,"Profit Model label","Fixed Expense") -> 5800 | H15: =GETPIVOTDATA("Expense/revenue",'Financial information 1 Pt1'!$E$5,"Profit Model label","Fixed Expense") -> 5800 | I15: =GETPIVOTDATA("Expense/revenue",'Financial information 1 Pt1'!$E$5,"Profit Model label","Fixed Expense") -> 5800 | ... M15: =GETPIVOTDATA("Expense/revenue",'Financial information 1 Pt1'!$E$5,"Profit Model label","Fixed Expense") -> 5800 | N15: =SUM(B15:M15) -> 69600
A16: Total Fixed Expense | B16: =GETPIVOTDATA("Expense/revenue",'Financial information 1 Pt1'!$E$5,"Profit Model label","Fixed Expense") -> 5800 | C16: =GETPIVOTDATA("Expense/revenue",'Financial information 1 Pt1'!$E$5,"Profit Model label","Fixed Expense") -> 5800 | D16: =GETPIVOTDATA("Expense/revenue",'Financial information 1 Pt1'!$E$5,"Profit Model label","Fixed Expense") -> 5800 | E16: =GETPIVOTDATA("Expense/revenue",'Financial information 1 Pt1'!$E$5,"Profit Model label","Fixed Expense") -> 5800 | F16: =GETPIVOTDATA("Expense/revenue",'Financial information 1 Pt1'!$E$5,"Profit Model label","Fixed Expense") -> 5800 | G16: =GETPIVOTDATA("Expense/revenue",'Financial information 1 Pt1'!$E$5,"Profit Model label","Fixed Expense") -> 5800 | H16: =GETPIVOTDATA("Expense/revenue",'Financial information 1 Pt1'!$E$5,"Profit Model label","Fixed Expense") -> 5800 | I16: =GETPIVOTDATA("Expense/revenue",'Financial information 1 Pt1'!$E$5,"Profit Model label","Fixed Expense") -> 5800 | ... M16: =GETPIVOTDATA("Expense/revenue",'Financial information 1 Pt1'!$E$5,"Profit Model label","Fixed Expense") -> 5800 | N16: =SUM(B16:M16) -> 69600
A18: Variable Expenses
A19: Coffee Variable expense | B19: =$E$2*GETPIVOTDATA("Expense/revenue",'Financial information 1 Pt1'!$E$5,"Profit Model label","Variable Expense: Coffee") -> 2000 | C19: =$E$2*GETPIVOTDATA("Expense/revenue",'Financial information 1 Pt1'!$E$5,"Profit Model label","Variable Expense: Coffee") -> 2000 | D19: =$E$2*GETPIVOTDATA("Expense/revenue",'Financial information 1 Pt1'!$E$5,"Profit Model label","Variable Expense: Coffee") -> 2000 | E19: =$E$2*GETPIVOTDATA("Expense/revenue",'Financial information 1 Pt1'!$E$5,"Profit Model label","Variable Expense: Coffee") -> 2000 | F19: =$E$2*GETPIVOTDATA("Expense/revenue",'Financial information 1 Pt1'!$E$5,"Profit Model label","Variable Expense: Coffee") -> 2000 | G19: =$E$2*GETPIVOTDATA("Expense/revenue",'Financial information 1 Pt1'!$E$5,"Profit Model label","Variable Expense: Coffee") -> 2000 | H19: =$E$2*GETPIVOTDATA("Expense/revenue",'Financial information 1 Pt1'!$E$5,"Profit Model label","Variable Expense: Coffee") -> 2000 | I19: =$E$2*GETPIVOTDATA("Expense/revenue",'Financial information 1 Pt1'!$E$5,"Profit Model label","Variable Expense: Coffee") -> 2000 | ... M19: =$E$2*GETPIVOTDATA("Expense/revenue",'Financial information 1 Pt1'!$E$5,"Profit Model label","Variable Expense: Coffee") -> 2000 | N19: =SUM(B19:M19) -> 24000
A20: Donut Variable expense | B20: =$E$2*GETPIVOTDATA("Expense/revenue",'Financial information 1 Pt1'!$E$5,"Profit Model label","Variable Expense: Donut") -> 2400 | C20: =$E$2*GETPIVOTDATA("Expense/revenue",'Financial information 1 Pt1'!$E$5,"Profit Model label","Variable Expense: Donut") -> 2400 | D20: =$E$2*GETPIVOTDATA("Expense/revenue",'Financial information 1 Pt1'!$E$5,"Profit Model label","Variable Expense: Donut") -> 2400 | E20: =$E$2*GETPIVOTDATA("Expense/revenue",'Financial information 1 Pt1'!$E$5,"Profit Model label","Variable Expense: Donut") -> 2400 | F20: =$E$2*GETPIVOTDATA("Expense/revenue",'Financial information 1 Pt1'!$E$5,"Profit Model label","Variable Expense: Donut") -> 2400 | G20: =$E$2*GETPIVOTDATA("Expense/revenue",'Financial information 1 Pt1'!$E$5,"Profit Model label","Variable Expense: Donut") -> 2400 | H20: =$E$2*GETPIVOTDATA("Expense/revenue",'Financial information 1 Pt1'!$E$5,"Profit Model label","Variable Expense: Donut") -> 2400 | I20: =$E$2*GETPIVOTDATA("Expense/revenue",'Financial information 1 Pt1'!$E$5,"Profit Model label","Variable Expense: Donut") -> 2400 | ... M20: =$E$2*GETPIVOTDATA("Expense/revenue",'Financial information 1 Pt1'!$E$5,"Profit Model label","Variable Expense: Donut") -> 2400
A21: Total Variable Expenses | B21: =SUM(B19:B20) -> 4400 | C21: =SUM(C19:C20) -> 4400 | D21: =SUM(D19:D20) -> 4400 | E21: =SUM(E19:E20) -> 4400 | F21: =SUM(F19:F20) -> 4400 | G21: =SUM(G19:G20) -> 4400 | H21: =SUM(H19:H20) -> 4400 | I21: =SUM(I19:I20) -> 4400 | ... M21: =SUM(M19:M20) -> 4400 | N21: =SUM(B21:M21) -> 52800
A22: Expenses: due to lost sales | B22: =B8*$F$2 -> 0 | C22: =C8*$F$2 -> 0 | D22: =D8*$F$2 -> 0 | E22: =E8*$F$2 -> 367.1864 | F22: =F8*$F$2 -> 1348.5717 | G22: =G8*$F$2 -> 501.68441 | H22: =H8*$F$2 -> 0 | I22: =I8*$F$2 -> 0 | ... M22: =M8*$F$2 -> 7286.4449 | N22: =SUM(B22:M22) -> 14450.904
A23: Total Expenses | B23: =B16+B21+B22 -> 10200 | C23: =C16+C21+C22 -> 10200 | D23: =D16+D21+D22 -> 10200 | E23: =E16+E21+E22 -> 10567.186 | F23: =F16+F21+F22 -> 11548.572 | G23: =G16+G21+G22 -> 10701.684 | H23: =H16+H21+H22 -> 10200 | I23: =I16+I21+I22 -> 10200 | ... M23: =M16+M21+M22 -> 17486.445 | N23: =SUM(B23:M23) -> 136850.9
A25: Profit Donuts and Coffee | B25: =B13-B23 -> 7147.01 | C25: =C13-C23 -> 9017.5947 | D25: =D13-D23 -> 8437.4092 | E25: =E13-E23 -> 11392.814 | F25: =F13-F23 -> 10411.428 | G25: =G13-G23 -> 11258.316 | H25: =H13-H23 -> 8162.235 | I25: =I13-I23 -> 11009.236 | ... M25: =M13-M23 -> 4473.5551 | N25: =SUM(B25:M25) -> 111605.66
B27: You should be able to copy from average to high and low and then just make some modifications
A28: HIGH DEMAND
A29: Month | B29: =B4 -> 44927 | C29: =C4 -> 44958 | D29: =D4 -> 44986 | E29: =E4 -> 45017 | F29: =F4 -> 45047 | G29: =G4 -> 45078 | H29: =H4 -> 45108 | I29: =I4 -> 45139 | ... M29: =M4 -> 45261 | N29: Yearly Total
A30: Demand | B30: =B5*(1+'Financial information 1 Pt1'!$B$34) -> 3552.6774 | C30: =C5*(1+'Financial information 1 Pt1'!$B$34) -> 4090.9117 | D30: =D5*(1+'Financial information 1 Pt1'!$B$34) -> 3923.9715 | E30: =E5*(1+'Financial information 1 Pt1'!$B$34) -> 5029.3225 | F30: =F5*(1+'Financial information 1 Pt1'!$B$34) -> 5428.4191 | G30: =G5*(1+'Financial information 1 Pt1'!$B$34) -> 5084.0183 | H30: =H5*(1+'Financial information 1 Pt1'!$B$34) -> 3844.794 | I30: =I5*(1+'Financial information 1 Pt1'!$B$34) -> 4663.9783 | ... M30: =M5*(1+'Financial information 1 Pt1'!$B$34) -> 7843.1543 | N30: =SUM(B30:M30) -> 60102.409
A31: satisfied demand | B31: =MIN(B30,$E$2) -> 3552.6774 | C31: =MIN(C30,$E$2) -> 4000 | D31: =MIN(D30,$E$2) -> 3923.9715 | E31: =MIN(E30,$E$2) -> 4000 | F31: =MIN(F30,$E$2) -> 4000 | G31: =MIN(G30,$E$2) -> 4000 | H31: =MIN(H30,$E$2) -> 3844.794 | I31: =MIN(I30,$E$2) -> 4000 | ... M31: =MIN(M30,$E$2) -> 4000 | N31: =SUM(B31:M31) -> 47321.443
A32: Extra donuts(over) | B32: =IF(B30<$E$2,$E$2-B30,0) -> 447.3226 | C32: =IF(C30<$E$2,$E$2-C30,0) -> 0 | D32: =IF(D30<$E$2,$E$2-D30,0) -> 76.028491 | E32: =IF(E30<$E$2,$E$2-E30,0) -> 0 | F32: =IF(F30<$E$2,$E$2-F30,0) -> 0 | G32: =IF(G30<$E$2,$E$2-G30,0) -> 0 | H32: =IF(H30<$E$2,$E$2-H30,0) -> 155.20598 | I32: =IF(I30<$E$2,$E$2-I30,0) -> 0 | ... M32: =IF(M30<$E$2,$E$2-M30,0) -> 0 | N32: =SUM(B32:M32) -> 678.55706
A33: Unsatisfied customers (short) | B33: =IF(B30>$E$2,B30-$E$2,0) -> 0 | C33: =IF(C30>$E$2,C30-$E$2,0) -> 90.911689 | D33: =IF(D30>$E$2,D30-$E$2,0) -> 0 | E33: =IF(E30>$E$2,E30-$E$2,0) -> 1029.3225 | F33: =IF(F30>$E$2,F30-$E$2,0) -> 1428.4191 | G33: =IF(G30>$E$2,G30-$E$2,0) -> 1084.0183 | H33: =IF(H30>$E$2,H30-$E$2,0) -> 0 | I33: =IF(I30>$E$2,I30-$E$2,0) -> 663.97833 | ... M33: =IF(M30>$E$2,M30-$E$2,0) -> 3843.1543 | N33: =SUM(B33:M33) -> 12780.966
A34: Revenue
A35: coffee | B35: =B31*'Financial information 1 Pt1'!$C$7 -> 10622.505 | C35: =C31*'Financial information 1 Pt1'!$C$7 -> 11960 | D35: =D31*'Financial information 1 Pt1'!$C$7 -> 11732.675 | E35: =E31*'Financial information 1 Pt1'!$C$7 -> 11960 | F35: =F31*'Financial information 1 Pt1'!$C$7 -> 11960 | G35: =G31*'Financial information 1 Pt1'!$C$7 -> 11960 | H35: =H31*'Financial information 1 Pt1'!$C$7 -> 11495.934 | I35: =I31*'Financial information 1 Pt1'!$C$7 -> 11960 | ... M35: =M31*'Financial information 1 Pt1'!$C$7 -> 11960 | N35: =SUM(B35:M35) -> 141491.11
A36: donut | B36: =B31*'Financial information 1 Pt1'!$C$8 -> 8881.6935 | C36: =C31*'Financial information 1 Pt1'!$C$8 -> 10000 | D36: =D31*'Financial information 1 Pt1'!$C$8 -> 9809.9288 | E36: =E31*'Financial information 1 Pt1'!$C$8 -> 10000 | F36: =F31*'Financial information 1 Pt1'!$C$8 -> 10000 | G36: =G31*'Financial information 1 Pt1'!$C$8 -> 10000 | H36: =H31*'Financial information 1 Pt1'!$C$8 -> 9611.9851 | I36: =I31*'Financial information 1 Pt1'!$C$8 -> 10000 | ... M36: =M31*'Financial information 1 Pt1'!$C$8 -> 10000 | N36: =SUM(B36:M36) -> 118303.61
A37: Revenue from day old sales | B37: =B32*$G$2 -> 559.15324 | C37: =C32*$G$2 -> 0 | D37: =D32*$G$2 -> 95.035614 | E37: =E32*$G$2 -> 0 | F37: =F32*$G$2 -> 0 | G37: =G32*$G$2 -> 0 | H37: =H32*$G$2 -> 194.00747 | I37: =I32*$G$2 -> 0 | ... M37: =M32*$G$2 -> 0 | N37: =SUM(B37:M37) -> 848.19633
A38: Total Revenue | B38: =SUM(B35:B37) -> 20063.352 | C38: =SUM(C35:C37) -> 21960 | D38: =SUM(D35:D37) -> 21637.639 | E38: =SUM(E35:E37) -> 21960 | F38: =SUM(F35:F37) -> 21960 | G38: =SUM(G35:G37) -> 21960 | H38: =SUM(H35:H37) -> 21301.927 | I38: =SUM(I35:I37) -> 21960 | ... M38: =SUM(M35:M37) -> 21960 | N38: =SUM(B38:M38) -> 260642.92
A39: Expenses
A40: Fixed Expenses | B40: =GETPIVOTDATA("Expense/revenue",'Financial information 1 Pt1'!$E$5,"Profit Model label","Fixed Expense") -> 5800 | C40: =GETPIVOTDATA("Expense/revenue",'Financial information 1 Pt1'!$E$5,"Profit Model label","Fixed Expense") -> 5800 | D40: =GETPIVOTDATA("Expense/revenue",'Financial information 1 Pt1'!$E$5,"Profit Model label","Fixed Expense") -> 5800 | E40: =GETPIVOTDATA("Expense/revenue",'Financial information 1 Pt1'!$E$5,"Profit Model label","Fixed Expense") -> 5800 | F40: =GETPIVOTDATA("Expense/revenue",'Financial information 1 Pt1'!$E$5,"Profit Model label","Fixed Expense") -> 5800 | G40: =GETPIVOTDATA("Expense/revenue",'Financial information 1 Pt1'!$E$5,"Profit Model label","Fixed Expense") -> 5800 | H40: =GETPIVOTDATA("Expense/revenue",'Financial information 1 Pt1'!$E$5,"Profit Model label","Fixed Expense") -> 5800 | I40: =GETPIVOTDATA("Expense/revenue",'Financial information 1 Pt1'!$E$5,"Profit Model label","Fixed Expense") -> 5800 | ... M40: =GETPIVOTDATA("Expense/revenue",'Financial information 1 Pt1'!$E$5,"Profit Model label","Fixed Expense") -> 5800 | N40: =SUM(B40:M40) -> 69600
A41: Total Fixed Expense | B41: =GETPIVOTDATA("Expense/revenue",'Financial information 1 Pt1'!$E$5,"Profit Model label","Fixed Expense") -> 5800 | C41: =GETPIVOTDATA("Expense/revenue",'Financial information 1 Pt1'!$E$5,"Profit Model label","Fixed Expense") -> 5800 | D41: =GETPIVOTDATA("Expense/revenue",'Financial information 1 Pt1'!$E$5,"Profit Model label","Fixed Expense") -> 5800 | E41: =GETPIVOTDATA("Expense/revenue",'Financial information 1 Pt1'!$E$5,"Profit Model label","Fixed Expense") -> 5800 | F41: =GETPIVOTDATA("Expense/revenue",'Financial information 1 Pt1'!$E$5,"Profit Model label","Fixed Expense") -> 5800 | G41: =GETPIVOTDATA("Expense/revenue",'Financial information 1 Pt1'!$E$5,"Profit Model label","Fixed Expense") -> 5800 | H41: =GETPIVOTDATA("Expense/revenue",'Financial information 1 Pt1'!$E$5,"Profit Model label","Fixed Expense") -> 5800 | I41: =GETPIVOTDATA("Expense/revenue",'Financial information 1 Pt1'!$E$5,"Profit Model label","Fixed Expense") -> 5800 | ... M41: =GETPIVOTDATA("Expense/revenue",'Financial information 1 Pt1'!$E$5,"Profit Model label","Fixed Expense") -> 5800 | N41: =SUM(B41:M41) -> 69600
A43: Variable Expenses
A44: Coffee Variable expense | B44: =$E$2*GETPIVOTDATA("Expense/revenue",'Financial information 1 Pt1'!$E$5,"Profit Model label","Variable Expense: Coffee") -> 2000 | C44: =$E$2*GETPIVOTDATA("Expense/revenue",'Financial information 1 Pt1'!$E$5,"Profit Model label","Variable Expense: Coffee") -> 2000 | D44: =$E$2*GETPIVOTDATA("Expense/revenue",'Financial information 1 Pt1'!$E$5,"Profit Model label","Variable Expense: Coffee") -> 2000 | E44: =$E$2*GETPIVOTDATA("Expense/revenue",'Financial information 1 Pt1'!$E$5,"Profit Model label","Variable Expense: Coffee") -> 2000 | F44: =$E$2*GETPIVOTDATA("Expense/revenue",'Financial information 1 Pt1'!$E$5,"Profit Model label","Variable Expense: Coffee") -> 2000 | G44: =$E$2*GETPIVOTDATA("Expense/revenue",'Financial information 1 Pt1'!$E$5,"Profit Model label","Variable Expense: Coffee") -> 2000 | H44: =$E$2*GETPIVOTDATA("Expense/revenue",'Financial information 1 Pt1'!$E$5,"Profit Model label","Variable Expense: Coffee") -> 2000 | I44: =$E$2*GETPIVOTDATA("Expense/revenue",'Financial information 1 Pt1'!$E$5,"Profit Model label","Variable Expense: Coffee") -> 2000 | ... M44: =$E$2*GETPIVOTDATA("Expense/revenue",'Financial information 1 Pt1'!$E$5,"Profit Model label","Variable Expense: Coffee") -> 2000 | N44: =SUM(B44:M44) -> 24000
...

Sheet Expected Values Pt4
A1: Remember that we use profits to fill in payoff tables like the ones we forecasted in the previous sheets. It would help if you filled in the table in C5:E7 and referenced those values to the other tables below. Use the probabilities found in Financial Information B42:44 for the regret tables | B1: PAYOFF TABLE | C1: Reminder: Format Cells to show 2 decimal places
I2: Fill in the space below for each method solved under each Decision Alternative. This is just a summary of the results on the left.
C3: State of Nature | H3: Summary of Results | I3: Methods
B4: Decision Alternatives | C4: Low | D4: Average | E4: High | H4: =B4 -> Decision Alternatives | I4: Maximin | J4: MaxiMax | K4: Laplace | L4: MinMax regret | M4: EVUII | N4: EOL
B5: CURRENT OPERATIONS | C5: ='Current operations Pt3 '!N75 -> 86688.554 | D5: ='Current operations Pt3 '!N25 -> 111605.66 | E5: ='Current operations Pt3 '!N50 -> 99900.02 | H5: CURRENT OPERATIONS | I5: =MIN(C13:E13) -> 86688.554 | J5: =MAX(C20:E20) -> 111605.66 | K5: =AVERAGE(C27:E27) -> 99398.076 | L5: =MAX(C34:E34) -> 10817.34 | M5: =SUMPRODUCT(C42:E42,C43:E43) -> 103695.83 | N5: =SUMPRODUCT(C58:E58,C59:E59) -> 4094.4223
B6: FRANCHISE | C6: ='Franchise operations Pt3'!N75 -> 72488.04 | D6: ='Franchise operations Pt3'!N25 -> 114133.09 | E6: ='Franchise operations Pt3'!N50 -> 109681.03 | H6: FRANCHISE | I6: =MIN(C14:E14) -> 72488.04 | J6: =MAX(C21:E21) -> 114133.09 | K6: =AVERAGE(C28:E28) -> 98767.385 | L6: =MAX(C35:E35) -> 14200.514 | M6: =SUMPRODUCT(C42:E42,C44:E44) -> 104691.06 | N6: =SUMPRODUCT(C58:E58,C60:E60) -> 3099.1854
B7: FOOD TRUCK | C7: ='Food Truck Pt 4'!N75 -> 60155.663 | D7: ='Food Truck Pt 4'!N25 -> 109752.02 | E7: ='Food Truck Pt 4'!N50 -> 110717.36 | H7: FOOD TRUCK | I7: =MIN(C15:E15) -> 60155.663 | J7: =MAX(C22:E22) -> 110717.36 | K7: =AVERAGE(C29:E29) -> 93541.681 | L7: =MAX(C36:E36) -> 26532.891 | M7: =SUMPRODUCT(C42:E42,C45:E45) -> 100074.08 | N7: =SUMPRODUCT(C58:E58,C61:E61) -> 7716.1644
B9: DM UNDER IGNORANCE | H9: Kiana should choose to:
B10: Maximin | H10: =H5 -> CURRENT OPERATIONS
C11: State of Nature
B12: Decision Alternatives | C12: Low | D12: Average | E12: High
B13: CURRENT OPERATIONS | C13: =C5 -> 86688.554 | D13: =D5 -> 111605.66 | E13: =E5 -> 99900.02
B14: FRANCHISE | C14: =C6 -> 72488.04 | D14: =D6 -> 114133.09 | E14: =E6 -> 109681.03
B15: FOOD TRUCK | C15: =C7 -> 60155.663 | D15: =D7 -> 109752.02 | E15: =E7 -> 110717.36
B17: Maximax
C18: State of Nature
B19: Decision Alternatives | C19: Low | D19: Average | E19: High
B20: CURRENT OPERATIONS | C20: =C13 -> 86688.554 | D20: =D13 -> 111605.66 | E20: =E13 -> 99900.02
B21: FRANCHISE | C21: =C14 -> 72488.04 | D21: =D14 -> 114133.09 | E21: =E14 -> 109681.03
B22: FOOD TRUCK | C22: =C15 -> 60155.663 | D22: =D15 -> 109752.02 | E22: =E15 -> 110717.36
B24: Laplace
C25: State of Nature
B26: Decision Alternatives | C26: Low | D26: Average | E26: High
B27: CURRENT OPERATIONS | C27: =C20 -> 86688.554 | D27: =D20 -> 111605.66 | E27: =E20 -> 99900.02 | F27: =AVERAGE(C27:E27) -> 99398.076 | G27: =MAX(F27:F29) -> 99398.076
B28: FRANCHISE | C28: =C21 -> 72488.04 | D28: =D21 -> 114133.09 | E28: =E21 -> 109681.03 | F28: =AVERAGE(C28:E28) -> 98767.385
B29: FOOD TRUCK | C29: =C22 -> 60155.663 | D29: =D22 -> 109752.02 | E29: =E22 -> 110717.36 | F29: =AVERAGE(C29:E29) -> 93541.681
B31: Minimax Regret
B32: Regret table | C32: State of Nature
B33: Decision Alternatives | C33: Low | D33: Average | E33: High
B34: CURRENT OPERATIONS | C34: =MAX(C$5:C$7)-C5 -> 0 | D34: =MAX(D$5:D$7)-D5 -> 2527.4317 | E34: =MAX(E$5:E$7)-E5 -> 10817.34
B35: FRANCHISE | C35: =MAX(C$5:C$7)-C6 -> 14200.514 | D35: =MAX(D$5:D$7)-D6 -> 0 | E35: =MAX(E$5:E$7)-E6 -> 1036.3305
B36: FOOD TRUCK | C36: =MAX(C$5:C$7)-C7 -> 26532.891 | D36: =MAX(D$5:D$7)-D7 -> 4381.0657 | E36: =MAX(E$5:E$7)-E7 -> 0
B38: DM UNDER RISK
B39: EVUII
C40: State of Nature
B41: Decision Alternatives | C41: Low | D41: Average | E41: High
B42: Probability | C42: ='Financial information 1 Pt1'!B41 -> 0.2 | D42: ='Financial information 1 Pt1'!B42 -> 0.55 | E42: ='Financial information 1 Pt1'!B43 -> 0.25
B43: CURRENT OPERATIONS | C43: =C5 -> 86688.554 | D43: =D5 -> 111605.66 | E43: =E5 -> 99900.02
B44: FRANCHISE | C44: =C6 -> 72488.04 | D44: =D6 -> 114133.09 | E44: =E6 -> 109681.03
B45: FOOD TRUCK | C45: =C7 -> 60155.663 | D45: =D7 -> 109752.02 | E45: =E7 -> 110717.36
...

Sheet Financial information 1 Pt1
A1: Donut Information
A2: Based on the below data, create the profit model for Donuts to Go.
A3: Assume that each customer will buy one donut and one cup of coffee
E5: Row Labels | F5: Sum of Expense/revenue
A6: Item | B6: Profit Model label | C6: Expense/revenue | E6: Fixed Expense | F6: 5800
A7: Revenue: Cup of Coffee | B7: Rev: Coffee | C7: 2.99 | E7: Rev: Coffee | F7: 2.99
A8: Revenue: Donut | B8: Rev: Donut | C8: 2.5 | E8: Rev: Donut | F8: 2.5
A9: Donut ingredients per donunt) | B9: Variable Expense: Donut | C9: 0.5 | E9: Variable Expense: Coffee | F9: 0.5
A10: paper products: napkins, plates etc per Donut | B10: Variable Expense: Donut | C10: 0.1 | E10: Variable Expense: Donut | F10: 0.6
A11: Insurance | B11: Fixed Expense | C11: 300 | E11: Grand Total | F11: 5806.59
A12: Maintenance & Repairs to equipment | B12: Fixed Expense | C12: 0
A13: Marketing & Promotion: Advertising | B13: Fixed Expense | C13: 100
A14: Coffee | B14: Variable Expense: Coffee | C14: 0.35
A15: Coffee cups | B15: Variable Expense: Coffee | C15: 0.15
A16: Payroll: Wages (Owner/ Manager) | B16: Fixed Expense | C16: 2400
